<?xml version="1.0" ?>
<mujoco>
  <compiler angle="radian" autolimits="true" assetdir="assets" meshdir="assets" texturedir="assets"/>
  <!--<statistic center="0.2 0 0.4" extent=".65"/>-->
  <visual>
    <headlight diffuse="0.6 0.6 0.6" ambient="0.3 0.3 0.3" specular="0 0 0"/>
    <rgba haze="0.15 0.25 0.35 1"/>
    <global azimuth="150" elevation="-20" offwidth="1280" offheight="1024"/>
  </visual>
  <asset>
    <texture type="skybox" builtin="gradient" rgb1="0.9 0.7 0.9" rgb2="0.94 0.97 0.97" width="512" height="3072"/>
    <texture type="2d" name="groundplane" builtin="checker" mark="edge" rgb1="0.2 0.3 0.4" rgb2="0.1 0.2 0.3" markrgb="0.8 0.8 0.8" width="300" height="300"/>
    <material name="groundplane" texture="groundplane" texuniform="true" texrepeat="5 5" reflectance="0.2"/>
    <texture name="T_simpleWoodTable" type="cube" height="1" width="1" file="robohive/furniture_sim/../furniture_sim/common/textures/wood0.png"/>
    <material name="M_simpleWoodTable" texture="T_simpleWoodTable" rgba="0.8 0.8 0.8 1" shininess="0.2" reflectance="0.3" texuniform="false"/>
    <texture name="T_simpleMarbleTable" type="cube" height="1" width="1" file="robohive/furniture_sim/../furniture_sim/common/textures/stone0.png"/>
    <material name="M_simpleMarbleTable" texture="T_simpleMarbleTable" rgba="0.75 0.75 0.75 1" shininess="1" reflectance="1" texuniform="false"/>
    <texture name="T_simpleGraniteTable" type="cube" height="1" width="1" file="robohive/furniture_sim/../furniture_sim/common/textures/stone1.png"/>
    <material name="M_simpleGraniteTable" texture="T_simpleGraniteTable" rgba="0.75 0.75 0.75 1" shininess="1" reflectance="1" texuniform="false"/>
    <texture type="2d" name="ball-sorting-toy-texture" file="ball_sorting_toy/texture.png"/>
    <material name="ball-sorting-toy-material" texture="ball-sorting-toy-texture" specular="0.2" shininess="0.2"/>
    <mesh name="ball-sorting-toy-model" file="ball_sorting_toy/model.obj" scale="0.12 0.12 0.12">
      <plugin instance="ball_sorting_toy-sdf"/>
    </mesh>
    <texture type="2d" name="i-box-light_wood" file="sort_shape/light_wood_planks.png"/>
    <material name="i-box-light_wood" texture="i-box-light_wood" specular="0.1" shininess="0.1" texrepeat="1 1"/>
    <mesh name="i-box-obj" file="sort_shape/block.obj" scale="0.08 0.08 0.08">
      <plugin instance="i-box-sdf"/>
    </mesh>
    <texture type="2d" name="sq-block-warm_wood" file="sort_shape/warm_wood_planks.png"/>
    <material name="sq-block-warm_wood" texture="sq-block-warm_wood" specular="0.1" shininess="0.1" texrepeat="1 1"/>
    <mesh name="sq-block-obj" file="sort_shape/square.obj" scale="0.07 0.07 0.07"/>
    <texture type="2d" name="tr-block-warm_wood" file="sort_shape/warm_wood_planks.png"/>
    <material name="tr-block-warm_wood" texture="tr-block-warm_wood" specular="0.1" shininess="0.1" texrepeat="1 1"/>
    <mesh name="tr-block-obj" file="sort_shape/triangle.obj" scale="0.07 0.07 0.07"/>
    <texture type="2d" name="hx-block-warm_wood" file="sort_shape/warm_wood_planks.png"/>
    <material name="hx-block-warm_wood" texture="hx-block-warm_wood" specular="0.1" shininess="0.1" texrepeat="1 1"/>
    <mesh name="hx-block-obj" file="sort_shape/hex.obj" scale="0.07 0.07 0.07"/>
    <texture type="2d" name="cr-block-warm_wood" file="sort_shape/warm_wood_planks.png"/>
    <material name="cr-block-warm_wood" texture="cr-block-warm_wood" specular="0.1" shininess="0.1" texrepeat="1 1"/>
    <mesh name="cr-block-obj" file="sort_shape/circle.obj" scale="0.07 0.07 0.07"/>
    <mesh name="object-model_visual_0" file="kitchen/mug/visual/model_normalized_0.obj" scale="0.105 0.105 0.105"/>
    <mesh name="object-model_visual_1" file="kitchen/mug/visual/model_normalized_1.obj" scale="0.105 0.105 0.105"/>
    <mesh name="object-model_collision_0" file="kitchen/mug/collision/model_normalized_collision_0.obj" scale="0.105 0.105 0.105"/>
    <mesh name="object-model_collision_1" file="kitchen/mug/collision/model_normalized_collision_1.obj" scale="0.105 0.105 0.105"/>
    <mesh name="object-model_collision_2" file="kitchen/mug/collision/model_normalized_collision_2.obj" scale="0.105 0.105 0.105"/>
    <mesh name="object-model_collision_3" file="kitchen/mug/collision/model_normalized_collision_3.obj" scale="0.105 0.105 0.105"/>
    <mesh name="object-model_collision_4" file="kitchen/mug/collision/model_normalized_collision_4.obj" scale="0.105 0.105 0.105"/>
    <mesh name="object-model_collision_5" file="kitchen/mug/collision/model_normalized_collision_5.obj" scale="0.105 0.105 0.105"/>
    <mesh name="object-model_collision_6" file="kitchen/mug/collision/model_normalized_collision_6.obj" scale="0.105 0.105 0.105"/>
    <mesh name="object-model_collision_7" file="kitchen/mug/collision/model_normalized_collision_7.obj" scale="0.105 0.105 0.105"/>
    <mesh name="object-model_collision_8" file="kitchen/mug/collision/model_normalized_collision_8.obj" scale="0.105 0.105 0.105"/>
    <mesh name="object-model_collision_9" file="kitchen/mug/collision/model_normalized_collision_9.obj" scale="0.105 0.105 0.105"/>
    <mesh name="object-model_collision_10" file="kitchen/mug/collision/model_normalized_collision_10.obj" scale="0.105 0.105 0.105"/>
    <mesh name="object-model_collision_11" file="kitchen/mug/collision/model_normalized_collision_11.obj" scale="0.105 0.105 0.105"/>
    <mesh name="object-model_collision_12" file="kitchen/mug/collision/model_normalized_collision_12.obj" scale="0.105 0.105 0.105"/>
    <mesh name="object-model_collision_13" file="kitchen/mug/collision/model_normalized_collision_13.obj" scale="0.105 0.105 0.105"/>
    <mesh name="object-model_collision_14" file="kitchen/mug/collision/model_normalized_collision_14.obj" scale="0.105 0.105 0.105"/>
    <mesh name="object-model_collision_15" file="kitchen/mug/collision/model_normalized_collision_15.obj" scale="0.105 0.105 0.105"/>
    <mesh name="object-model_collision_16" file="kitchen/mug/collision/model_normalized_collision_16.obj" scale="0.105 0.105 0.105"/>
    <mesh name="object-model_collision_17" file="kitchen/mug/collision/model_normalized_collision_17.obj" scale="0.105 0.105 0.105"/>
    <mesh name="object-model_collision_18" file="kitchen/mug/collision/model_normalized_collision_18.obj" scale="0.105 0.105 0.105"/>
    <mesh name="object-model_collision_19" file="kitchen/mug/collision/model_normalized_collision_19.obj" scale="0.105 0.105 0.105"/>
    <mesh name="object-model_collision_20" file="kitchen/mug/collision/model_normalized_collision_20.obj" scale="0.105 0.105 0.105"/>
    <mesh name="object-model_collision_21" file="kitchen/mug/collision/model_normalized_collision_21.obj" scale="0.105 0.105 0.105"/>
    <mesh name="object-model_collision_22" file="kitchen/mug/collision/model_normalized_collision_22.obj" scale="0.105 0.105 0.105"/>
    <mesh name="object-model_collision_23" file="kitchen/mug/collision/model_normalized_collision_23.obj" scale="0.105 0.105 0.105"/>
    <mesh name="object-model_collision_24" file="kitchen/mug/collision/model_normalized_collision_24.obj" scale="0.105 0.105 0.105"/>
    <mesh name="object-model_collision_25" file="kitchen/mug/collision/model_normalized_collision_25.obj" scale="0.105 0.105 0.105"/>
    <mesh name="object-model_collision_26" file="kitchen/mug/collision/model_normalized_collision_26.obj" scale="0.105 0.105 0.105"/>
    <mesh name="object-model_collision_27" file="kitchen/mug/collision/model_normalized_collision_27.obj" scale="0.105 0.105 0.105"/>
    <mesh name="object-model_collision_28" file="kitchen/mug/collision/model_normalized_collision_28.obj" scale="0.105 0.105 0.105"/>
    <mesh name="object-model_collision_29" file="kitchen/mug/collision/model_normalized_collision_29.obj" scale="0.105 0.105 0.105"/>
    <mesh name="object-model_collision_30" file="kitchen/mug/collision/model_normalized_collision_30.obj" scale="0.105 0.105 0.105"/>
    <mesh name="object-model_collision_31" file="kitchen/mug/collision/model_normalized_collision_31.obj" scale="0.105 0.105 0.105"/>
    <material name="Mat.1" specular="0.5" shininess="0.00226274" rgba="0.171600 0.780000 0.435240 1.0"/>
    <material name="material.047" specular="0.5" shininess="0.00226274" rgba="0.930000 0.930000 0.930000 1.0"/>
    <material class="ur5e" name="ur5e-black" rgba="0.033 0.033 0.033 1"/>
    <material class="ur5e" name="ur5e-jointgray" rgba="0.278 0.278 0.278 1"/>
    <material class="ur5e" name="ur5e-linkgray" rgba="0.82 0.82 0.82 1"/>
    <material class="ur5e" name="ur5e-urblue" rgba="0.49 0.678 0.8 1"/>
    <mesh file="ur5e/base_0.obj"/>
    <mesh file="ur5e/base_1.obj"/>
    <mesh file="ur5e/shoulder_0.obj"/>
    <mesh file="ur5e/shoulder_1.obj"/>
    <mesh file="ur5e/shoulder_2.obj"/>
    <mesh file="ur5e/upperarm_0.obj"/>
    <mesh file="ur5e/upperarm_1.obj"/>
    <mesh file="ur5e/upperarm_2.obj"/>
    <mesh file="ur5e/upperarm_3.obj"/>
    <mesh file="ur5e/forearm_0.obj"/>
    <mesh file="ur5e/forearm_1.obj"/>
    <mesh file="ur5e/forearm_2.obj"/>
    <mesh file="ur5e/forearm_3.obj"/>
    <mesh file="ur5e/wrist1_0.obj"/>
    <mesh file="ur5e/wrist1_1.obj"/>
    <mesh file="ur5e/wrist1_2.obj"/>
    <mesh file="ur5e/wrist2_0.obj"/>
    <mesh file="ur5e/wrist2_1.obj"/>
    <mesh file="ur5e/wrist2_2.obj"/>
    <mesh file="ur5e/wrist3.obj"/>
    <material class="2f85" name="2f85-metal" rgba="0.58 0.58 0.58 1"/>
    <material class="2f85" name="2f85-silicone" rgba="0.1882 0.1882 0.1882 1"/>
    <material class="2f85" name="2f85-gray" rgba="0.4627 0.4627 0.4627 1"/>
    <material class="2f85" name="2f85-black" rgba="0.149 0.149 0.149 1"/>
    <mesh class="2f85" file="robotiq_2f85/base_mount.stl"/>
    <mesh class="2f85" file="robotiq_2f85/base.stl"/>
    <mesh class="2f85" file="robotiq_2f85/driver.stl"/>
    <mesh class="2f85" file="robotiq_2f85/coupler.stl"/>
    <mesh class="2f85" file="robotiq_2f85/follower.stl"/>
    <mesh class="2f85" file="robotiq_2f85/pad.stl"/>
    <mesh class="2f85" file="robotiq_2f85/silicone_pad.stl"/>
    <mesh class="2f85" file="robotiq_2f85/spring_link.stl"/>
  </asset>
  z
  <default>
    <default class="viz_simpleWoodTable">
      <geom group="1" contype="0" conaffinity="0" type="mesh" material="M_simpleWoodTable"/>
    </default>
    <default class="viz_simpleMarbleTable">
      <geom group="1" contype="0" conaffinity="0" type="mesh" material="M_simpleMarbleTable"/>
    </default>
    <default class="viz_simpleGraniteTable">
      <geom group="1" contype="0" conaffinity="0" type="mesh" material="M_simpleGraniteTable"/>
    </default>
    <default class="body_simpleTable">
      <geom contype="1" conaffinity="1" group="4" rgba=".4 .5 .6 1"/>
      <joint limited="true" damping="1" frictionloss="0.5" armature=".01"/>
    </default>
    <default class="object-obj-visual">
      <geom solimp="0.998 0.998 0.001" solref="0.001 1" density="100" friction="0.95 0.3 0.1" group="0" type="mesh" contype="0" conaffinity="0"/>
    </default>
    <default class="object-obj-collision">
      <geom solimp="0.998 0.998 0.001" solref="0.001 1" friction="0.95 0.3 0.1" density="100" group="3" type="mesh"/>
    </default>
    <default class="ur5e">
      <material specular="0.5" shininess="0.25"/>
      <joint axis="0 1 0" range="-6.28319 6.28319" armature="0.1"/>
      <general gaintype="fixed" biastype="affine" ctrlrange="-6.2831 6.2831" gainprm="2000" biasprm="0 -2000 -400" forcerange="-150 150"/>
      <default class="ur5e-size3">
        <default class="ur5e-size3_limited">
          <joint range="-3.1415 3.1415"/>
          <general ctrlrange="-3.1415 3.1415"/>
        </default>
      </default>
      <default class="ur5e-size1">
        <general gainprm="500" biasprm="0 -500 -100" forcerange="-28 28"/>
      </default>
      <default class="ur5e-visual">
        <geom type="mesh" contype="0" conaffinity="0" group="2"/>
      </default>
      <default class="ur5e-collision">
        <geom type="capsule" group="3"/>
        <default class="ur5e-eef_collision">
          <geom type="cylinder"/>
        </default>
      </default>
      <site size="0.001" rgba="0.5 0.5 0.5 0.3" group="4"/>
    </default>
    <default class="2f85">
      <mesh scale="0.001 0.001 0.001"/>
      <general biastype="affine"/>
      <joint axis="1 0 0"/>
      <default class="2f85-driver">
        <joint range="0 0.8" armature="0.005" damping="0.1" solimplimit="0.95 0.99 0.001" solreflimit="0.005 1"/>
      </default>
      <default class="2f85-follower">
        <joint range="-0.872664 0.872664" armature="0.001" pos="0 -0.018 0.0065" solimplimit="0.95 0.99 0.001" solreflimit="0.005 1"/>
      </default>
      <default class="2f85-spring_link">
        <joint range="-0.29670597283 0.8" armature="0.001" stiffness="0.05" springref="2.62" damping="0.00125"/>
      </default>
      <default class="2f85-coupler">
        <joint range="-1.57 0" armature="0.001" solimplimit="0.95 0.99 0.001" solreflimit="0.005 1"/>
      </default>
      <default class="2f85-visual">
        <geom type="mesh" contype="0" conaffinity="0" group="0"/>
      </default>
      <default class="2f85-collision">
        <geom type="mesh" group="3"/>
        <default class="2f85-pad_box1">
          <geom mass="0" type="box" pos="0 -0.0026 0.028125" size="0.011 0.004 0.009375" friction="4" solimp="0.95 0.99 0.001" solref="0.004 1" priority="1" rgba="0.55 0.55 0.55 1"/>
        </default>
        <default class="2f85-pad_box2">
          <geom mass="0" type="box" pos="0 -0.0026 0.009375" size="0.011 0.004 0.009375" friction="3" solimp="0.95 0.99 0.001" solref="0.004 1" priority="1" rgba="0.45 0.45 0.45 1"/>
        </default>
      </default>
    </default>
  </default>
  <option timestep="0.002" integrator="implicitfast" sdf_iterations="20" sdf_initpoints="40"/>
  <extension>
    <plugin plugin="mujoco.sdf.sdflib">
      <instance name="ball_sorting_toy-sdf">
        <config key="aabb" value="0"/>
      </instance>
      <instance name="i-box-sdf">
        <config key="aabb" value="0"/>
      </instance>
    </plugin>
    <plugin plugin="mujoco.elasticity.cable"/>
  </extension>
  <worldbody>
    <light name="key" pos="1 0.5 1.27" dir="-1 -0.5 -0.5" cutoff="45" diffuse="0.3 0.3 0.3" directional="true"/>
    <light name="fill" pos="0.8 -0.7 1.17" dir="-0.8 0.5 -0.6" cutoff="60" diffuse="0.18 0.18 0.18" directional="true"/>
    <light name="back" pos="-0.8 0 1.97" dir="-1 0 1" cutoff="50" diffuse="0.5 0.5 0.5" directional="true"/>
    <camera name="left" pos="0.44 0.355 1.095" fovy="42.5" xyaxes="-1.0 0.0 0.0 0.0 -0.4046485876119067 0.9144722634086225"/>
    <camera name="right" pos="0.375 -0.355 1.095" fovy="42.5" xyaxes="1.0 0.0 0.0 -0.0 0.4046485876119067 0.9144722634086225"/>
    <camera name="stereo_left" pos="-0.3 0.03 1.27" resolution="640 360" focalpixel="426.215 426.332" sensorsize="0.0098 0.00735" xyaxes="-0.029986509105671005 -0.9995503035223668 0.0 0.4468516474737887 -0.01340554942421366 0.8945076279130302"/>
    <camera name="stereo_right" pos="-0.3 -0.03 1.27" resolution="640 360" focalpixel="426.215 426.332" sensorsize="0.0098 0.00735" xyaxes="0.029986509105671005 -0.9995503035223668 0.0 0.4468516474737887 0.01340554942421366 0.8945076279130302"/>
    <camera name="stereo_far_right" pos="-0.30000000000000004 -0.6 1.47" resolution="640 360" focalpixel="426.215 426.332" sensorsize="0.0098 0.00735" xyaxes="0.5144957554275265 -0.8574929257125442 0.0 0.44130893612810324 0.2647853616768619 0.857400218763172"/>
    <camera name="stereo_far_left" pos="-0.30000000000000004 0.6 1.47" resolution="640 360" focalpixel="426.215 426.332" sensorsize="0.0098 0.00735" xyaxes="-0.5144957554275265 -0.8574929257125442 0.0 0.44130893612810324 -0.2647853616768619 0.857400218763172"/>
    <body name="simpleTable/simpleWoodTable" pos="0.4 0 0" quat="0.7071 0 0 0.7071">
      <body name="simpleTable/simpleWoodTable/simpleWoodTable" pos="0 0 0" childclass="body_simpleTable">
        <geom class="viz_simpleWoodTable" type="box" size=".6 .375 .025" pos="0 0 0.735"/>
        <geom class="viz_simpleWoodTable" type="box" size="0.59 0.26 .05" pos="0 0 0.66"/>
        <geom class="viz_simpleWoodTable" type="box" size="0.025 0.025 0.305" pos="-0.565 0.235 0.305"/>
        <geom class="viz_simpleWoodTable" type="box" size="0.025 0.025 0.305" pos="-0.565 -0.235 0.305"/>
        <geom class="viz_simpleWoodTable" type="box" size="0.025 0.025 0.305" pos="0.565 0.235 0.305"/>
        <geom class="viz_simpleWoodTable" type="box" size="0.025 0.025 0.305" pos="0.565 -0.235 0.305"/>
        <geom type="box" size=".6 .375 .025" pos="0 0 0.735" mass="40"/>
        <geom type="box" size="0.59 0.26 .05" pos="0 0 0.66"/>
        <geom type="box" size="0.025 0.025 0.305" pos="-0.565 0.235 0.305"/>
        <geom type="box" size="0.025 0.025 0.305" pos="-0.565 -0.235 0.305"/>
        <geom type="box" size="0.025 0.025 0.305" pos="0.565 0.235 0.305"/>
        <geom type="box" size="0.025 0.025 0.305" pos="0.565 -0.235 0.305"/>
      </body>
    </body>
    <body name="ball-sorting-toy" pos="0.465 0.27 0.82" quat="1 0 0 0">
      <joint type="free"/>
      <geom type="sdf" name="ball-sorting-toy-sdf" mesh="ball-sorting-toy-model" quat="-0.5 -0.5 0.5 0.5" mass="0.1" material="ball-sorting-toy-material" contype="1" conaffinity="1">
        <plugin instance="ball_sorting_toy-sdf"/>
      </geom>
      <site name="hole-1" pos="0.08 0 0.05" size="0.03" rgba="1 0 0 0" type="sphere"/>
    </body>
    <body name="cylinder-orange" pos="0.35 0.15 0.79" quat="0 0 1 0">
      <joint type="free" name="cylinder-orange"/>
      <geom name="cylinder-orange-cylinder" type="cylinder" size="0.0175 0.0175" rgba="1 0.5 0 1" mass="0.1" condim="4" solimp="0.998 0.998 0.001" solref="0.001 1" friction="3 0.003 0.001" density="50"/>
      <site name="cylinder-orange" pos="0 0 0" size="0.01" rgba="1 0 0 0" type="sphere"/>
    </body>
    <body name="insertion-box" pos="0.5 0 0.82">
      <joint type="free"/>
      <geom type="sdf" mesh="i-box-obj" material="i-box-light_wood" contype="1" conaffinity="1">
        <plugin instance="i-box-sdf"/>
      </geom>
      <site name="insertion-box-hexblock" pos="0.03 -0.033 0.1" size="0.02" rgba="1 1 1 0"/>
      <site name="insertion-box-squareblock" pos="-0.03 0.03 0.1" size="0.02" rgba="1 1 1 0"/>
      <site name="insertion-box-circleblock" pos="0.031 0.031 0.1" size="0.02" rgba="1 1 1 0"/>
      <site name="insertion-box-triangleblock" pos="-0.03 -0.033 0.1" size="0.02" rgba="1 1 1 0"/>
    </body>
    <body name="square" pos="0.3 -0.0 0.82">
      <joint type="free"/>
      <geom type="mesh" mesh="sq-block-obj" material="sq-block-warm_wood"/>
      <site name="square" pos="0 0 0" size="0.02" rgba="1 1 1 0"/>
    </body>
    <body name="triangle" pos="0.4 -0.0 0.82">
      <joint type="free"/>
      <geom type="mesh" mesh="tr-block-obj" material="tr-block-warm_wood"/>
      <site name="triangle" pos="0 0 0" size="0.02" rgba="1 1 1 0"/>
    </body>
    <body name="hex" pos="0.3 0.1 0.82">
      <joint type="free"/>
      <geom type="mesh" mesh="hx-block-obj" material="hx-block-warm_wood"/>
      <site name="hex" pos="0 0 0" size="0.02" rgba="1 1 1 0"/>
    </body>
    <body name="circle" pos="0.4 0.1 0.82">
      <joint type="free"/>
      <geom type="mesh" mesh="cr-block-obj" material="cr-block-warm_wood"/>
      <site name="circle" pos="0 0 0" size="0.02" rgba="1 1 1 0"/>
    </body>
    <body pos="0.3 -0.25 0.85" name="object">
      <joint name="object-joint" type="free"/>
      <!-- Visual Mesh -->
      <geom mesh="object-model_visual_0" material="Mat.1" class="object-obj-visual"/>
      <geom mesh="object-model_visual_1" material="material.047" class="object-obj-visual"/>
      <geom mesh="object-model_collision_0" rgba="0.1174793161753791 0.5793107960816033 0.5290620308757062 1" class="object-obj-collision"/>
      <geom mesh="object-model_collision_1" rgba="0.6075152690574965 0.8813571257331253 0.6436784734661839 1" class="object-obj-collision"/>
      <geom mesh="object-model_collision_2" rgba="0.19701349673440594 0.7358018727685581 0.010343794958613817 1" class="object-obj-collision"/>
      <geom mesh="object-model_collision_3" rgba="0.6225694468969222 0.1427224978510926 0.9628324754182733 1" class="object-obj-collision"/>
      <geom mesh="object-model_collision_4" rgba="0.10125372664786558 0.33926349689528856 0.48845091507115534 1" class="object-obj-collision"/>
      <geom mesh="object-model_collision_5" rgba="0.5859608270512853 0.20919035966850974 0.18403049864025223 1" class="object-obj-collision"/>
      <geom mesh="object-model_collision_6" rgba="0.43005264076631644 0.35841459545002397 0.02966834150837605 1" class="object-obj-collision"/>
      <geom mesh="object-model_collision_7" rgba="0.002550569730908614 0.4647076119399359 0.6009794835393313 1" class="object-obj-collision"/>
      <geom mesh="object-model_collision_8" rgba="0.48810414908265587 0.9699233873096058 0.7237243384029707 1" class="object-obj-collision"/>
      <geom mesh="object-model_collision_9" rgba="0.3633598825185179 0.06187434794810398 0.7120427900428941 1" class="object-obj-collision"/>
      <geom mesh="object-model_collision_10" rgba="0.43240333994277935 0.26113941218478764 0.7375858685719027 1" class="object-obj-collision"/>
      <geom mesh="object-model_collision_11" rgba="0.34444078966667935 0.8763334937257719 0.11679342183519914 1" class="object-obj-collision"/>
      <geom mesh="object-model_collision_12" rgba="0.853719426012822 0.5865036391042499 0.36871654054067116 1" class="object-obj-collision"/>
      <geom mesh="object-model_collision_13" rgba="0.7542531392146475 0.014543455558879259 0.2662723531482164 1" class="object-obj-collision"/>
      <geom mesh="object-model_collision_14" rgba="0.1202148370270183 0.1462201307266271 0.27140562052680806 1" class="object-obj-collision"/>
      <geom mesh="object-model_collision_15" rgba="0.05214732560354951 0.6738678421635459 0.7892357990082819 1" class="object-obj-collision"/>
      <geom mesh="object-model_collision_16" rgba="0.41864586064621845 0.016819650014356147 0.23880956944735032 1" class="object-obj-collision"/>
      <geom mesh="object-model_collision_17" rgba="0.442321218587437 0.8144299494864184 0.5357151912441211 1" class="object-obj-collision"/>
      <geom mesh="object-model_collision_18" rgba="0.06751548078950054 0.609463545889391 0.7048611241489902 1" class="object-obj-collision"/>
      <geom mesh="object-model_collision_19" rgba="0.18687880650918276 0.11483617588414463 0.7443472102838782 1" class="object-obj-collision"/>
      <geom mesh="object-model_collision_20" rgba="0.4221019928609986 0.8206371088485039 0.8087202864514037 1" class="object-obj-collision"/>
      <geom mesh="object-model_collision_21" rgba="0.727640571671573 0.942995303565944 0.09988234123841977 1" class="object-obj-collision"/>
      <geom mesh="object-model_collision_22" rgba="0.1128018112212178 0.2933629057383358 0.8950167282987856 1" class="object-obj-collision"/>
      <geom mesh="object-model_collision_23" rgba="0.9308475580122998 0.7964959456967153 0.9094684444703248 1" class="object-obj-collision"/>
      <geom mesh="object-model_collision_24" rgba="0.9197822763914906 0.0595186498480208 0.4570891782900953 1" class="object-obj-collision"/>
      <geom mesh="object-model_collision_25" rgba="0.02803899304097235 0.6275418109627217 0.32819778644491393 1" class="object-obj-collision"/>
      <geom mesh="object-model_collision_26" rgba="0.5434814627156016 0.678445575883793 0.11362121829911331 1" class="object-obj-collision"/>
      <geom mesh="object-model_collision_27" rgba="0.8008818108608105 0.052073694204573084 0.9922631699324616 1" class="object-obj-collision"/>
      <geom mesh="object-model_collision_28" rgba="0.3287868724806102 0.7180140410415875 0.7674539779110389 1" class="object-obj-collision"/>
      <geom mesh="object-model_collision_29" rgba="0.5192243895240098 0.8640503642535602 0.6227601822278257 1" class="object-obj-collision"/>
      <geom mesh="object-model_collision_30" rgba="0.2178372520246672 0.5125200460386138 0.04341171437591651 1" class="object-obj-collision"/>
      <geom mesh="object-model_collision_31" rgba="0.2502942591508711 0.786558007642431 0.205668602875264 1" class="object-obj-collision"/>
    </body>
    <body>
      <composite prefix="rope_" type="cable" curve="s" count="50 1 1" size="0.43" initial="none" offset="0.3 -0.25 1.1">
        <plugin plugin="mujoco.elasticity.cable">
          <!--Units are in Pa (SI)-->
          <config key="twist" value="10.0"/>
          <config key="bend" value="10.0"/>
          <config key="vmax" value="0.005"/>
        </plugin>
        <joint kind="main" damping="0.0005"/>
        <geom type="capsule" size="0.008" rgba="0.7 0 0 1" condim="1" mass="0.001"/>
      </composite>
      <freejoint/>
    </body>
    <body name="rope_anchor" pos="0.3 -0.25 1.1" quat="1 0 0 0">
      <!-- translate along x -->
      <joint name="jx" type="slide" axis="1 0 0" damping="500" frictionloss="200" armature="5"/>
      <!-- translate along y -->
      <joint name="jy" type="slide" axis="0 1 0" damping="500" frictionloss="200" armature="5"/>
      <!-- optional: rotate about z in the plane -->
      <!-- <joint name="jz" type="hinge" axis="0 0 1"
               damping="200" frictionloss="50" armature="1"/> -->
      <!-- your geoms here -->
      <geom type="sphere" size="0.01" contype="0" conaffinity="0" rgba="1 1 1 0"/>
    </body>
    <body name="ur5e" childclass="ur5e" pos="0 0 0.77" quat="1 0 0 1">
      <inertial mass="4.0" pos="0 0 0" diaginertia="0.00443333156 0.00443333156 0.0072"/>
      <geom mesh="base_0" material="ur5e-black" class="ur5e-visual"/>
      <geom mesh="base_1" material="ur5e-jointgray" class="ur5e-visual"/>
      <body name="ur5e-shoulder_link" pos="0 0 0.163">
        <inertial mass="3.7" pos="0 0 0" diaginertia="0.0102675 0.0102675 0.00666"/>
        <joint name="ur5e-shoulder_pan_joint" class="ur5e-size3" axis="0 0 1"/>
        <geom mesh="shoulder_0" material="ur5e-urblue" class="ur5e-visual"/>
        <geom mesh="shoulder_1" material="ur5e-black" class="ur5e-visual"/>
        <geom mesh="shoulder_2" material="ur5e-jointgray" class="ur5e-visual"/>
        <geom class="ur5e-collision" size="0.06 0.06" pos="0 0 -0.04"/>
        <body name="ur5e-upper_arm_link" pos="0 0.138 0" quat="1 0 1 0">
          <inertial mass="8.393" pos="0 0 0.2125" diaginertia="0.133886 0.133886 0.0151074"/>
          <joint name="ur5e-shoulder_lift_joint" class="ur5e-size3"/>
          <geom mesh="upperarm_0" material="ur5e-linkgray" class="ur5e-visual"/>
          <geom mesh="upperarm_1" material="ur5e-black" class="ur5e-visual"/>
          <geom mesh="upperarm_2" material="ur5e-jointgray" class="ur5e-visual"/>
          <geom mesh="upperarm_3" material="ur5e-urblue" class="ur5e-visual"/>
          <geom class="ur5e-collision" pos="0 -0.04 0" quat="1 1 0 0" size="0.06 0.06"/>
          <geom class="ur5e-collision" size="0.05 0.2" pos="0 0 0.2"/>
          <body name="ur5e-forearm_link" pos="0 -0.131 0.425">
            <inertial mass="2.275" pos="0 0 0.196" diaginertia="0.0311796 0.0311796 0.004095"/>
            <joint name="ur5e-elbow_joint" class="ur5e-size3_limited"/>
            <geom mesh="forearm_0" material="ur5e-urblue" class="ur5e-visual"/>
            <geom mesh="forearm_1" material="ur5e-linkgray" class="ur5e-visual"/>
            <geom mesh="forearm_2" material="ur5e-black" class="ur5e-visual"/>
            <geom mesh="forearm_3" material="ur5e-jointgray" class="ur5e-visual"/>
            <geom class="ur5e-collision" pos="0 0.08 0" quat="1 1 0 0" size="0.055 0.06"/>
            <geom class="ur5e-collision" size="0.038 0.19" pos="0 0 0.2"/>
            <body name="ur5e-wrist_1_link" pos="0 0 0.392" quat="1 0 1 0">
              <inertial mass="1.219" pos="0 0.127 0" diaginertia="0.0025599 0.0025599 0.0021942"/>
              <joint name="ur5e-wrist_1_joint" class="ur5e-size1"/>
              <geom mesh="wrist1_0" material="ur5e-black" class="ur5e-visual"/>
              <geom mesh="wrist1_1" material="ur5e-urblue" class="ur5e-visual"/>
              <geom mesh="wrist1_2" material="ur5e-jointgray" class="ur5e-visual"/>
              <geom class="ur5e-collision" pos="0 0.05 0" quat="1 1 0 0" size="0.04 0.07"/>
              <body name="ur5e-wrist_2_link" pos="0 0.127 0">
                <inertial mass="1.219" pos="0 0 0.1" diaginertia="0.0025599 0.0025599 0.0021942"/>
                <joint name="ur5e-wrist_2_joint" axis="0 0 1" class="ur5e-size1"/>
                <geom mesh="wrist2_0" material="ur5e-black" class="ur5e-visual"/>
                <geom mesh="wrist2_1" material="ur5e-urblue" class="ur5e-visual"/>
                <geom mesh="wrist2_2" material="ur5e-jointgray" class="ur5e-visual"/>
                <geom class="ur5e-collision" size="0.04 0.06" pos="0 0 0.04"/>
                <geom class="ur5e-collision" pos="0 0.02 0.1" quat="1 1 0 0" size="0.04 0.04"/>
                <body name="ur5e-wrist_3_link" pos="0 0 0.1">
                  <inertial mass="0.1889" pos="0 0.0771683 0" quat="1 0 0 1" diaginertia="0.000132134 9.90863e-05 9.90863e-05"/>
                  <joint name="ur5e-wrist_3_joint" class="ur5e-size1"/>
                  <geom material="ur5e-linkgray" mesh="wrist3" class="ur5e-visual" pos="0 0 0.0001"/>
                  <geom class="ur5e-eef_collision" pos="0 0.08 0" quat="1 1 0 0" size="0.04 0.02"/>
                  <site name="ur5e-attachment_site" pos="0 0.1 0" quat="-1 1 0 0"/>
                  <body name="ur5e-eef" pos="0 0.1 0" quat="-1 1 0 0">
                    <body name="gripper" pos="0 0 0" quat="1 0 0 1">
                      <geom class="2f85-visual" mesh="base_mount" material="2f85-black"/>
                      <geom class="2f85-collision" mesh="base_mount"/>
                      <body name="gripper-base" pos="0 0 0.0038" quat="1 0 0 0">
                        <inertial mass="0.05" pos="0 -2.70394e-05 0.0354675" quat="1 -0.00152849 0 0" diaginertia="0.000260285 0.000225381 0.000152708"/>
                        <geom class="2f85-visual" mesh="base" material="2f85-black"/>
                        <geom class="2f85-collision" mesh="base"/>
                        <site name="gripper-pinch" pos="0 0 0.145" type="sphere" rgba="0.9 0.0 0.0 1" size="0.002"/>
                        <camera name="wrist" pos="-0.1 0.0 0.01" quat="-0.11 0.7 0.7 -0.11" fovy="42.5"/>
                        <!-- Right-hand side 4-bar linkage -->
                        <body name="gripper-right_driver" pos="0 0.0306011 0.054904">
                          <inertial mass="0.00899563" pos="2.96931e-12 0.0177547 0.00107314" quat="0.681301 0.732003 0 0" diaginertia="1.72352e-06 1.60906e-06 3.22006e-07"/>
                          <joint name="gripper-right_driver_joint" class="2f85-driver"/>
                          <geom class="2f85-visual" mesh="driver" material="2f85-gray"/>
                          <geom class="2f85-collision" mesh="driver"/>
                          <body name="gripper-right_coupler" pos="0 0.0315 -0.0041">
                            <inertial mass="0.0140974" pos="0 0.00301209 0.0232175" quat="0.705636 -0.0455904 0.0455904 0.705636" diaginertia="4.16206e-06 3.52216e-06 8.88131e-07"/>
                            <joint name="gripper-right_coupler_joint" class="2f85-coupler"/>
                            <geom class="2f85-visual" mesh="coupler" material="2f85-black"/>
                            <geom class="2f85-collision" mesh="coupler"/>
                          </body>
                        </body>
                        <body name="gripper-right_spring_link" pos="0 0.0132 0.0609">
                          <inertial mass="0.0221642" pos="-8.65005e-09 0.0181624 0.0212658" quat="0.663403 -0.244737 0.244737 0.663403" diaginertia="8.96853e-06 6.71733e-06 2.63931e-06"/>
                          <joint name="gripper-right_spring_link_joint" class="2f85-spring_link"/>
                          <geom class="2f85-visual" mesh="spring_link" material="2f85-black"/>
                          <geom class="2f85-collision" mesh="spring_link"/>
                          <body name="gripper-right_follower" pos="0 0.055 0.0375">
                            <inertial mass="0.0125222" pos="0 -0.011046 0.0124786" quat="1 0.1664 0 0" diaginertia="2.67415e-06 2.4559e-06 6.02031e-07"/>
                            <joint name="gripper-right_follower_joint" class="2f85-follower"/>
                            <geom class="2f85-visual" mesh="follower" material="2f85-black"/>
                            <geom class="2f85-collision" mesh="follower"/>
                            <body name="gripper-right_pad" pos="0 -0.0189 0.01352">
                              <geom class="2f85-pad_box1" name="gripper-right_pad1"/>
                              <geom class="2f85-pad_box2" name="gripper-right_pad2"/>
                              <inertial mass="0.0035" pos="0 -0.0025 0.0185" quat="0.707107 0 0 0.707107" diaginertia="4.73958e-07 3.64583e-07 1.23958e-07"/>
                              <geom class="2f85-visual" mesh="pad"/>
                              <body name="gripper-right_silicone_pad">
                                <geom class="2f85-visual" mesh="silicone_pad" material="2f85-black"/>
                              </body>
                            </body>
                          </body>
                        </body>
                        <!-- Left-hand side 4-bar linkage -->
                        <body name="gripper-left_driver" pos="0 -0.0306011 0.054904" quat="0 0 0 1">
                          <inertial mass="0.00899563" pos="0 0.0177547 0.00107314" quat="0.681301 0.732003 0 0" diaginertia="1.72352e-06 1.60906e-06 3.22006e-07"/>
                          <joint name="gripper-left_driver_joint" class="2f85-driver"/>
                          <geom class="2f85-visual" mesh="driver" material="2f85-gray"/>
                          <geom class="2f85-collision" mesh="driver"/>
                          <body name="gripper-left_coupler" pos="0 0.0315 -0.0041">
                            <inertial mass="0.0140974" pos="0 0.00301209 0.0232175" quat="0.705636 -0.0455904 0.0455904 0.705636" diaginertia="4.16206e-06 3.52216e-06 8.88131e-07"/>
                            <joint name="gripper-left_coupler_joint" class="2f85-coupler"/>
                            <geom class="2f85-visual" mesh="coupler" material="2f85-black"/>
                            <geom class="2f85-collision" mesh="coupler"/>
                          </body>
                        </body>
                        <body name="gripper-left_spring_link" pos="0 -0.0132 0.0609" quat="0 0 0 1">
                          <inertial mass="0.0221642" pos="-8.65005e-09 0.0181624 0.0212658" quat="0.663403 -0.244737 0.244737 0.663403" diaginertia="8.96853e-06 6.71733e-06 2.63931e-06"/>
                          <joint name="gripper-left_spring_link_joint" class="2f85-spring_link"/>
                          <geom class="2f85-visual" mesh="spring_link" material="2f85-black"/>
                          <geom class="2f85-collision" mesh="spring_link"/>
                          <body name="gripper-left_follower" pos="0 0.055 0.0375">
                            <inertial mass="0.0125222" pos="0 -0.011046 0.0124786" quat="1 0.1664 0 0" diaginertia="2.67415e-06 2.4559e-06 6.02031e-07"/>
                            <joint name="gripper-left_follower_joint" class="2f85-follower"/>
                            <geom class="2f85-visual" mesh="follower" material="2f85-black"/>
                            <geom class="2f85-collision" mesh="follower"/>
                            <body name="gripper-left_pad" pos="0 -0.0189 0.01352">
                              <geom class="2f85-pad_box1" name="gripper-left_pad1"/>
                              <geom class="2f85-pad_box2" name="gripper-left_pad2"/>
                              <inertial mass="0.0035" pos="0 -0.0025 0.0185" quat="1 0 0 1" diaginertia="4.73958e-07 3.64583e-07 1.23958e-07"/>
                              <geom class="2f85-visual" mesh="pad"/>
                              <body name="gripper-left_silicone_pad">
                                <geom class="2f85-visual" mesh="silicone_pad" material="2f85-black"/>
                              </body>
                            </body>
                          </body>
                        </body>
                      </body>
                    </body>
                  </body>
                </body>
              </body>
            </body>
          </body>
        </body>
      </body>
    </body>
    <body mocap="true" name="gripper-mocap" pos="0 0.3 0.97" quat="0 0 1 0">
      <site name="gripper-mocap-site" size="0.002" type="sphere" rgba="0.13 0.3 0.2 1"/>
    </body>
  </worldbody>
  <equality>
    <weld body1="rope_B_first" body2="rope_anchor" relpose="0 0 0  1 0 0 0" solref="0.001 3" solimp="0.9 0.95 0.01"/>
    <connect anchor="0 0 0" body1="gripper-right_follower" body2="gripper-right_coupler" solimp="0.95 0.99 0.001" solref="0.005 1"/>
    <connect anchor="0 0 0" body1="gripper-left_follower" body2="gripper-left_coupler" solimp="0.95 0.99 0.001" solref="0.005 1"/>
    <joint joint1="gripper-right_driver_joint" joint2="gripper-left_driver_joint" polycoef="0 1 0 0 0" solimp="0.95 0.99 0.001" solref="0.005 1"/>
    <weld name="gripper-control" site1="gripper-mocap-site" site2="gripper-pinch"/>
  </equality>
  <contact>
    <exclude body1="gripper-base" body2="gripper-left_driver"/>
    <exclude body1="gripper-base" body2="gripper-right_driver"/>
    <exclude body1="gripper-base" body2="gripper-left_spring_link"/>
    <exclude body1="gripper-base" body2="gripper-right_spring_link"/>
    <exclude body1="gripper-right_coupler" body2="gripper-right_follower"/>
    <exclude body1="gripper-left_coupler" body2="gripper-left_follower"/>
  </contact>
  <!--This adds stability to the model by having a tendon that distributes the forces between both
      joints, such that the equality constraint doesn't have to do that much work in order to equalize
      both joints. Since both joints share the same sign, we split the force between both equally by
      setting coef=0.5-->
  <tendon>
    <fixed name="gripper-split">
      <joint joint="gripper-right_driver_joint" coef="0.5"/>
      <joint joint="gripper-left_driver_joint" coef="0.5"/>
    </fixed>
  </tendon>
  <!--The general actuator below is a customized position actuator (with some damping) where
      gainprm[0] != kp (see http://mujoco.org/book/modeling.html#position).
      The reason why gainprm[0] != kp is because the control input range has to be re-scaled to
      [0, 255]. The joint range is currently set at [0, 0.8], the control range is [0, 255] and
      kp = 100. Tau = Kp * scale * control_input - Kp * error, max(Kp * scale * control_input) = 0.8,
      hence scale = 0.8 * 100 / 255-->
  <actuator>
    <general class="2f85" name="gripper-fingers_actuator" tendon="gripper-split" forcerange="-5 5" ctrlrange="0 1" gainprm="80 0 0" biasprm="0 -100 -10"/>
  </actuator>
</mujoco>